Traceback (most recent call last):
  File "c:\users\jmmau\anaconda3\envs\workenv\lib\site-packages\jupyter_cache\executors\utils.py", line 56, in single_nb_execution
    record_timing=False,
  File "c:\users\jmmau\anaconda3\envs\workenv\lib\site-packages\nbclient\client.py", line 1087, in execute
    return NotebookClient(nb=nb, resources=resources, km=km, **kwargs).execute()
  File "c:\users\jmmau\anaconda3\envs\workenv\lib\site-packages\nbclient\util.py", line 74, in wrapped
    return just_run(coro(*args, **kwargs))
  File "c:\users\jmmau\anaconda3\envs\workenv\lib\site-packages\nbclient\util.py", line 53, in just_run
    return loop.run_until_complete(coro)
  File "c:\users\jmmau\anaconda3\envs\workenv\lib\asyncio\base_events.py", line 587, in run_until_complete
    return future.result()
  File "c:\users\jmmau\anaconda3\envs\workenv\lib\site-packages\nbclient\client.py", line 541, in async_execute
    cell, index, execution_count=self.code_cells_executed + 1
  File "c:\users\jmmau\anaconda3\envs\workenv\lib\site-packages\nbclient\client.py", line 832, in async_execute_cell
    self._check_raise_for_error(cell, exec_reply)
  File "c:\users\jmmau\anaconda3\envs\workenv\lib\site-packages\nbclient\client.py", line 740, in _check_raise_for_error
    raise CellExecutionError.from_cell_and_msg(cell, exec_reply['content'])
nbclient.exceptions.CellExecutionError: An error occurred while executing the following cell:
------------------
from pydae import ssa
from pendulum import pendulum_class

------------------

[1;31m---------------------------------------------------------------------------[0m
[1;31mModuleNotFoundError[0m                       Traceback (most recent call last)
[1;32m<ipython-input-3-440574a2138a>[0m in [0;36m<module>[1;34m[0m
[1;32m----> 1[1;33m [1;32mfrom[0m [0mpydae[0m [1;32mimport[0m [0mssa[0m[1;33m[0m[1;33m[0m[0m
[0m[0;32m      2[0m [1;32mfrom[0m [0mpendulum[0m [1;32mimport[0m [0mpendulum_class[0m[1;33m[0m[1;33m[0m[0m

[1;32m~\anaconda3\envs\workenv\lib\site-packages\pydae\ssa.py[0m in [0;36m<module>[1;34m[0m
[0;32m      8[0m [1;33m[0m[0m
[0;32m      9[0m [1;32mimport[0m [0mnumpy[0m [1;32mas[0m [0mnp[0m[1;33m[0m[1;33m[0m[0m
[1;32m---> 10[1;33m [1;32mimport[0m [0mpandas[0m [1;32mas[0m [0mpd[0m[1;33m[0m[1;33m[0m[0m
[0m[0;32m     11[0m [1;32mimport[0m [0mscipy[0m[1;33m[0m[1;33m[0m[0m
[0;32m     12[0m [1;33m[0m[0m

[1;31mModuleNotFoundError[0m: No module named 'pandas'
ModuleNotFoundError: No module named 'pandas'

